ERROR 2025-05-31 16:08:57,826 log 1 140167585393464 Service Unavailable: /health/
ERROR 2025-05-31 16:09:02,956 log 1 140167585393464 Service Unavailable: /health/
ERROR 2025-05-31 16:09:33,162 log 1 140167585393464 Service Unavailable: /health/
ERROR 2025-05-31 16:10:03,305 log 1 140167585393464 Service Unavailable: /health/
ERROR 2025-05-31 16:10:33,469 log 1 140167585393464 Service Unavailable: /health/
ERROR 2025-05-31 16:11:24,880 log 1 140605756898104 Service Unavailable: /health/
ERROR 2025-05-31 16:11:27,800 exception 1 140605756898104 Invalid HTTP_HOST header: '127.0.0.1:8000'. You may need to add '127.0.0.1' to ALLOWED_HOSTS.
Traceback (most recent call last):
  File "/usr/local/lib/python3.12/site-packages/asgiref/sync.py", line 518, in thread_handler
    raise exc_info[1]
  File "/usr/local/lib/python3.12/site-packages/django/core/handlers/exception.py", line 42, in inner
    response = await get_response(request)
               ^^^^^^^^^^^^^^^^^^^^^^^^^^^
  File "/usr/local/lib/python3.12/site-packages/django/utils/deprecation.py", line 132, in __acall__
    response = await sync_to_async(
               ^^^^^^^^^^^^^^^^^^^^
  File "/usr/local/lib/python3.12/site-packages/asgiref/sync.py", line 468, in __call__
    ret = await asyncio.shield(exec_coro)
          ^^^^^^^^^^^^^^^^^^^^^^^^^^^^^^^
  File "/usr/local/lib/python3.12/concurrent/futures/thread.py", line 59, in run
    result = self.fn(*self.args, **self.kwargs)
             ^^^^^^^^^^^^^^^^^^^^^^^^^^^^^^^^^^
  File "/usr/local/lib/python3.12/site-packages/asgiref/sync.py", line 522, in thread_handler
    return func(*args, **kwargs)
           ^^^^^^^^^^^^^^^^^^^^^
  File "/usr/local/lib/python3.12/site-packages/django/middleware/common.py", line 48, in process_request
    host = request.get_host()
           ^^^^^^^^^^^^^^^^^^
  File "/usr/local/lib/python3.12/site-packages/django/http/request.py", line 186, in get_host
    raise DisallowedHost(msg)
django.core.exceptions.DisallowedHost: Invalid HTTP_HOST header: '127.0.0.1:8000'. You may need to add '127.0.0.1' to ALLOWED_HOSTS.
ERROR 2025-05-31 16:11:55,019 log 1 140605756898104 Service Unavailable: /health/
ERROR 2025-05-31 16:13:19,972 exception 1 139795260758840 Invalid HTTP_HOST header: '127.0.0.1:8000'. You may need to add '127.0.0.1' to ALLOWED_HOSTS.
Traceback (most recent call last):
  File "/usr/local/lib/python3.12/site-packages/asgiref/sync.py", line 518, in thread_handler
    raise exc_info[1]
  File "/usr/local/lib/python3.12/site-packages/django/core/handlers/exception.py", line 42, in inner
    response = await get_response(request)
               ^^^^^^^^^^^^^^^^^^^^^^^^^^^
  File "/usr/local/lib/python3.12/site-packages/django/utils/deprecation.py", line 132, in __acall__
    response = await sync_to_async(
               ^^^^^^^^^^^^^^^^^^^^
  File "/usr/local/lib/python3.12/site-packages/asgiref/sync.py", line 468, in __call__
    ret = await asyncio.shield(exec_coro)
          ^^^^^^^^^^^^^^^^^^^^^^^^^^^^^^^
  File "/usr/local/lib/python3.12/concurrent/futures/thread.py", line 59, in run
    result = self.fn(*self.args, **self.kwargs)
             ^^^^^^^^^^^^^^^^^^^^^^^^^^^^^^^^^^
  File "/usr/local/lib/python3.12/site-packages/asgiref/sync.py", line 522, in thread_handler
    return func(*args, **kwargs)
           ^^^^^^^^^^^^^^^^^^^^^
  File "/usr/local/lib/python3.12/site-packages/django/middleware/common.py", line 48, in process_request
    host = request.get_host()
           ^^^^^^^^^^^^^^^^^^
  File "/usr/local/lib/python3.12/site-packages/django/http/request.py", line 186, in get_host
    raise DisallowedHost(msg)
django.core.exceptions.DisallowedHost: Invalid HTTP_HOST header: '127.0.0.1:8000'. You may need to add '127.0.0.1' to ALLOWED_HOSTS.
ERROR 2025-05-31 16:18:18,133 log 1 140372825082680 Internal Server Error: /account/signup/
Traceback (most recent call last):
  File "/usr/local/lib/python3.12/site-packages/django/utils/module_loading.py", line 30, in import_string
    return cached_import(module_path, class_name)
           ^^^^^^^^^^^^^^^^^^^^^^^^^^^^^^^^^^^^^^
  File "/usr/local/lib/python3.12/site-packages/django/utils/module_loading.py", line 16, in cached_import
    return getattr(module, class_name)
           ^^^^^^^^^^^^^^^^^^^^^^^^^^^
AttributeError: module 'redis.connection' has no attribute 'HiredisParser'. Did you mean: '_HiredisParser'?

The above exception was the direct cause of the following exception:

Traceback (most recent call last):
  File "/usr/local/lib/python3.12/site-packages/asgiref/sync.py", line 518, in thread_handler
    raise exc_info[1]
  File "/usr/local/lib/python3.12/site-packages/django/core/handlers/exception.py", line 42, in inner
    response = await get_response(request)
               ^^^^^^^^^^^^^^^^^^^^^^^^^^^
  File "/usr/local/lib/python3.12/site-packages/asgiref/sync.py", line 518, in thread_handler
    raise exc_info[1]
  File "/usr/local/lib/python3.12/site-packages/django/core/handlers/base.py", line 253, in _get_response_async
    response = await wrapped_callback(
               ^^^^^^^^^^^^^^^^^^^^^^^
  File "/usr/local/lib/python3.12/site-packages/asgiref/sync.py", line 468, in __call__
    ret = await asyncio.shield(exec_coro)
          ^^^^^^^^^^^^^^^^^^^^^^^^^^^^^^^
  File "/usr/local/lib/python3.12/concurrent/futures/thread.py", line 59, in run
    result = self.fn(*self.args, **self.kwargs)
             ^^^^^^^^^^^^^^^^^^^^^^^^^^^^^^^^^^
  File "/usr/local/lib/python3.12/site-packages/asgiref/sync.py", line 522, in thread_handler
    return func(*args, **kwargs)
           ^^^^^^^^^^^^^^^^^^^^^
  File "/usr/local/lib/python3.12/site-packages/django/views/generic/base.py", line 104, in view
    return self.dispatch(request, *args, **kwargs)
           ^^^^^^^^^^^^^^^^^^^^^^^^^^^^^^^^^^^^^^^
  File "/usr/local/lib/python3.12/site-packages/django/views/generic/base.py", line 143, in dispatch
    return handler(request, *args, **kwargs)
           ^^^^^^^^^^^^^^^^^^^^^^^^^^^^^^^^^
  File "/usr/local/lib/python3.12/site-packages/django/views/generic/edit.py", line 182, in post
    return super().post(request, *args, **kwargs)
           ^^^^^^^^^^^^^^^^^^^^^^^^^^^^^^^^^^^^^^
  File "/usr/local/lib/python3.12/site-packages/django/views/generic/edit.py", line 151, in post
    return self.form_valid(form)
           ^^^^^^^^^^^^^^^^^^^^^
  File "/app/core/apps/account/views.py", line 51, in form_valid
    login(self.request, user, backend='core.apps.account.backends.EmailAuthBackend')
  File "/usr/local/lib/python3.12/site-packages/django/contrib/auth/__init__.py", line 187, in login
    request.session.cycle_key()
  File "/usr/local/lib/python3.12/site-packages/django/contrib/sessions/backends/base.py", line 432, in cycle_key
    self.create()
  File "/usr/local/lib/python3.12/site-packages/django/contrib/sessions/backends/cache.py", line 55, in create
    self._session_key = self._get_new_session_key()
                        ^^^^^^^^^^^^^^^^^^^^^^^^^^^
  File "/usr/local/lib/python3.12/site-packages/django/contrib/sessions/backends/base.py", line 196, in _get_new_session_key
    if not self.exists(session_key):
           ^^^^^^^^^^^^^^^^^^^^^^^^
  File "/usr/local/lib/python3.12/site-packages/django/contrib/sessions/backends/cache.py", line 117, in exists
    bool(session_key) and (self.cache_key_prefix + session_key) in self._cache
                          ^^^^^^^^^^^^^^^^^^^^^^^^^^^^^^^^^^^^^^^^^^^^^^^^^^^^
  File "/usr/local/lib/python3.12/site-packages/django/core/cache/backends/base.py", line 301, in __contains__
    return self.has_key(key)
           ^^^^^^^^^^^^^^^^^
  File "/usr/local/lib/python3.12/site-packages/django_redis/cache.py", line 29, in _decorator
    return method(self, *args, **kwargs)
           ^^^^^^^^^^^^^^^^^^^^^^^^^^^^^
  File "/usr/local/lib/python3.12/site-packages/django_redis/cache.py", line 138, in has_key
    return self.client.has_key(*args, **kwargs)
           ^^^^^^^^^^^^^^^^^^^^^^^^^^^^^^^^^^^^
  File "/usr/local/lib/python3.12/site-packages/django_redis/client/default.py", line 664, in has_key
    client = self.get_client(write=False)
             ^^^^^^^^^^^^^^^^^^^^^^^^^^^^
  File "/usr/local/lib/python3.12/site-packages/django_redis/client/default.py", line 105, in get_client
    self._clients[index] = self.connect(index)
                           ^^^^^^^^^^^^^^^^^^^
  File "/usr/local/lib/python3.12/site-packages/django_redis/client/default.py", line 118, in connect
    return self.connection_factory.connect(self._server[index])
           ^^^^^^^^^^^^^^^^^^^^^^^^^^^^^^^^^^^^^^^^^^^^^^^^^^^^
  File "/usr/local/lib/python3.12/site-packages/django_redis/pool.py", line 70, in connect
    params = self.make_connection_params(url)
             ^^^^^^^^^^^^^^^^^^^^^^^^^^^^^^^^
  File "/usr/local/lib/python3.12/site-packages/django_redis/pool.py", line 42, in make_connection_params
    "parser_class": self.get_parser_cls(),
                    ^^^^^^^^^^^^^^^^^^^^^
  File "/usr/local/lib/python3.12/site-packages/django_redis/pool.py", line 99, in get_parser_cls
    return import_string(cls)
           ^^^^^^^^^^^^^^^^^^
  File "/usr/local/lib/python3.12/site-packages/django/utils/module_loading.py", line 32, in import_string
    raise ImportError(
ImportError: Module "redis.connection" does not define a "HiredisParser" attribute/class
